"GET /skills/33 HTTP/1.1" 200 18771
This is an info message
This is a warning message
This is an error message
This is a critical message
"GET /account/ HTTP/1.1" 200 18682
C:\Users\admin\PycharmProjects\pythonProjectDjango\itstep\itstep\settings.py changed, reloading.
Watching for file changes with StatReloader
C:\Users\admin\PycharmProjects\pythonProjectDjango\itstep\account\views.py changed, reloading.
Watching for file changes with StatReloader
C:\Users\admin\PycharmProjects\pythonProjectDjango\itstep\itstep\settings.py changed, reloading.
Watching for file changes with StatReloader
C:\Users\admin\PycharmProjects\pythonProjectDjango\itstep\itstep\settings.py changed, reloading.
Watching for file changes with StatReloader
"GET / HTTP/1.1" 200 23098
"GET /static/css/styles.css HTTP/1.1" 200 4278
"GET /static/debug_toolbar/css/toolbar.css HTTP/1.1" 200 16675
"GET /static/images/logo.png HTTP/1.1" 200 6241
"GET /static/debug_toolbar/js/toolbar.js HTTP/1.1" 200 14601
"GET /static/images/sky.jpg HTTP/1.1" 200 75829
"GET /static/debug_toolbar/css/print.css HTTP/1.1" 200 43
"GET /static/debug_toolbar/js/utils.js HTTP/1.1" 200 4742
Not Found: /favicon.ico
"GET /favicon.ico HTTP/1.1" 404 16532
"GET /account/ HTTP/1.1" 200 18644
"GET /media/users/2024/09/03/4.jpg HTTP/1.1" 200 8170
"GET /account/edit/ HTTP/1.1" 200 19929
"GET /account/edit/ HTTP/1.1" 200 19928
"POST /account/logout/ HTTP/1.1" 200 18163
"GET /account/login/ HTTP/1.1" 200 19385
"GET /static/images/login.png HTTP/1.1" 200 139113
"GET / HTTP/1.1" 200 22824
"GET /media/users/2024/09/02/photo-1549692520-acc6669e2f0c_FM85C9b.jpg HTTP/1.1" 304 0
Not Found: /favicon.ico
"GET /favicon.ico HTTP/1.1" 404 16531
Not Found: /favicon.ico
"GET /favicon.ico HTTP/1.1" 404 16531
"GET /account/login/ HTTP/1.1" 200 19385
"POST /account/login/ HTTP/1.1" 200 19487
"POST /account/login/ HTTP/1.1" 302 0
"GET /account/ HTTP/1.1" 200 18682
"GET /media/users/2024/09/02/photo-1549692520-acc6669e2f0c_FM85C9b.jpg HTTP/1.1" 200 13483
"POST /account/logout/ HTTP/1.1" 200 18163
"GET /account/login/ HTTP/1.1" 200 19384
"POST /account/login/ HTTP/1.1" 302 0
"GET /account/ HTTP/1.1" 200 18682
"GET /account/edit/ HTTP/1.1" 200 20004
"POST /account/logout/ HTTP/1.1" 200 18163
"GET /account/login/ HTTP/1.1" 200 19385
"GET /account/register/ HTTP/1.1" 200 20028
"GET /blog/create/ HTTP/1.1" 302 0
"GET /account/login/?next=/blog/create/ HTTP/1.1" 200 19416
"POST /account/login/?next=/blog/create/ HTTP/1.1" 302 0
"GET /blog/create/ HTTP/1.1" 200 21288
"POST /account/logout/ HTTP/1.1" 200 18163
"GET /account/login/ HTTP/1.1" 200 19385
"GET /account/ HTTP/1.1" 302 0
"GET /account/login/?next=/account/ HTTP/1.1" 200 19408
Watching for file changes with StatReloader
Not Found: /account/profile/
"GET /account/profile/ HTTP/1.1" 404 17323
"GET /account HTTP/1.1" 301 0
"GET /account/ HTTP/1.1" 302 0
"GET /account/login/?next=/account/ HTTP/1.1" 200 19409
"GET /account/register/ HTTP/1.1" 200 20027
"GET /account/login/ HTTP/1.1" 200 19384
"POST /account/login/ HTTP/1.1" 302 0
"GET /account/ HTTP/1.1" 200 18683
"GET /account/edit/ HTTP/1.1" 200 20004
"POST /account/edit/ HTTP/1.1" 200 20085
"POST /account/edit/ HTTP/1.1" 200 20094
"POST /account/edit/ HTTP/1.1" 200 20094
Internal Server Error: /blog/tag/create/
Traceback (most recent call last):
  File "C:\Users\admin\PycharmProjects\pythonProjectDjango\venv\Lib\site-packages\django\core\handlers\exception.py", line 55, in inner
    response = get_response(request)
               ^^^^^^^^^^^^^^^^^^^^^
  File "C:\Users\admin\PycharmProjects\pythonProjectDjango\venv\Lib\site-packages\django\core\handlers\base.py", line 197, in _get_response
    response = wrapped_callback(request, *callback_args, **callback_kwargs)
               ^^^^^^^^^^^^^^^^^^^^^^^^^^^^^^^^^^^^^^^^^^^^^^^^^^^^^^^^^^^^
  File "C:\Users\admin\PycharmProjects\pythonProjectDjango\itstep\blog\views.py", line 112, in create_tag
    if form.is_valid():
       ^^^^^^^^^^^^^^^
  File "C:\Users\admin\PycharmProjects\pythonProjectDjango\venv\Lib\site-packages\django\forms\forms.py", line 197, in is_valid
    return self.is_bound and not self.errors
                                 ^^^^^^^^^^^
  File "C:\Users\admin\PycharmProjects\pythonProjectDjango\venv\Lib\site-packages\django\forms\forms.py", line 192, in errors
    self.full_clean()
  File "C:\Users\admin\PycharmProjects\pythonProjectDjango\venv\Lib\site-packages\django\forms\forms.py", line 328, in full_clean
    self._clean_form()
  File "C:\Users\admin\PycharmProjects\pythonProjectDjango\venv\Lib\site-packages\django\forms\forms.py", line 349, in _clean_form
    cleaned_data = self.clean()
                   ^^^^^^^^^^^^
  File "C:\Users\admin\PycharmProjects\pythonProjectDjango\itstep\blog\forms.py", line 46, in clean
    if len(cleaned_data.get("name")) < 3:
       ^^^^^^^^^^^^^^^^^^^^^^^^^^^^^
TypeError: object of type 'NoneType' has no len()
Internal Server Error: /blog/tag/create/
Traceback (most recent call last):
  File "C:\Users\admin\PycharmProjects\pythonProjectDjango\venv\Lib\site-packages\django\db\backends\utils.py", line 105, in _execute
    return self.cursor.execute(sql, params)
           ^^^^^^^^^^^^^^^^^^^^^^^^^^^^^^^^
  File "C:\Users\admin\PycharmProjects\pythonProjectDjango\venv\Lib\site-packages\django\db\backends\sqlite3\base.py", line 329, in execute
    return super().execute(query, params)
           ^^^^^^^^^^^^^^^^^^^^^^^^^^^^^^
sqlite3.IntegrityError: UNIQUE constraint failed: blog_tag.slug

The above exception was the direct cause of the following exception:

Traceback (most recent call last):
  File "C:\Users\admin\PycharmProjects\pythonProjectDjango\venv\Lib\site-packages\django\core\handlers\exception.py", line 55, in inner
    response = get_response(request)
               ^^^^^^^^^^^^^^^^^^^^^
  File "C:\Users\admin\PycharmProjects\pythonProjectDjango\venv\Lib\site-packages\django\core\handlers\base.py", line 197, in _get_response
    response = wrapped_callback(request, *callback_args, **callback_kwargs)
               ^^^^^^^^^^^^^^^^^^^^^^^^^^^^^^^^^^^^^^^^^^^^^^^^^^^^^^^^^^^^
  File "C:\Users\admin\PycharmProjects\pythonProjectDjango\itstep\blog\views.py", line 116, in create_tag
    tag.save()
  File "C:\Users\admin\PycharmProjects\pythonProjectDjango\itstep\blog\models.py", line 97, in save
    super(Tag, self).save(*args, **kwargs)
  File "C:\Users\admin\PycharmProjects\pythonProjectDjango\venv\Lib\site-packages\django\db\models\base.py", line 822, in save
    self.save_base(
  File "C:\Users\admin\PycharmProjects\pythonProjectDjango\venv\Lib\site-packages\django\db\models\base.py", line 909, in save_base
    updated = self._save_table(
              ^^^^^^^^^^^^^^^^^
  File "C:\Users\admin\PycharmProjects\pythonProjectDjango\venv\Lib\site-packages\django\db\models\base.py", line 1071, in _save_table
    results = self._do_insert(
              ^^^^^^^^^^^^^^^^
  File "C:\Users\admin\PycharmProjects\pythonProjectDjango\venv\Lib\site-packages\django\db\models\base.py", line 1112, in _do_insert
    return manager._insert(
           ^^^^^^^^^^^^^^^^
  File "C:\Users\admin\PycharmProjects\pythonProjectDjango\venv\Lib\site-packages\django\db\models\manager.py", line 87, in manager_method
    return getattr(self.get_queryset(), name)(*args, **kwargs)
           ^^^^^^^^^^^^^^^^^^^^^^^^^^^^^^^^^^^^^^^^^^^^^^^^^^^
  File "C:\Users\admin\PycharmProjects\pythonProjectDjango\venv\Lib\site-packages\django\db\models\query.py", line 1847, in _insert
    return query.get_compiler(using=using).execute_sql(returning_fields)
           ^^^^^^^^^^^^^^^^^^^^^^^^^^^^^^^^^^^^^^^^^^^^^^^^^^^^^^^^^^^^^
  File "C:\Users\admin\PycharmProjects\pythonProjectDjango\venv\Lib\site-packages\django\db\models\sql\compiler.py", line 1823, in execute_sql
    cursor.execute(sql, params)
  File "C:\Users\admin\PycharmProjects\pythonProjectDjango\venv\Lib\site-packages\django\db\backends\utils.py", line 79, in execute
    return self._execute_with_wrappers(
           ^^^^^^^^^^^^^^^^^^^^^^^^^^^^
  File "C:\Users\admin\PycharmProjects\pythonProjectDjango\venv\Lib\site-packages\django\db\backends\utils.py", line 92, in _execute_with_wrappers
    return executor(sql, params, many, context)
           ^^^^^^^^^^^^^^^^^^^^^^^^^^^^^^^^^^^^
  File "C:\Users\admin\PycharmProjects\pythonProjectDjango\venv\Lib\site-packages\django\db\backends\utils.py", line 100, in _execute
    with self.db.wrap_database_errors:
  File "C:\Users\admin\PycharmProjects\pythonProjectDjango\venv\Lib\site-packages\django\db\utils.py", line 91, in __exit__
    raise dj_exc_value.with_traceback(traceback) from exc_value
  File "C:\Users\admin\PycharmProjects\pythonProjectDjango\venv\Lib\site-packages\django\db\backends\utils.py", line 105, in _execute
    return self.cursor.execute(sql, params)
           ^^^^^^^^^^^^^^^^^^^^^^^^^^^^^^^^
  File "C:\Users\admin\PycharmProjects\pythonProjectDjango\venv\Lib\site-packages\django\db\backends\sqlite3\base.py", line 329, in execute
    return super().execute(query, params)
           ^^^^^^^^^^^^^^^^^^^^^^^^^^^^^^
django.db.utils.IntegrityError: UNIQUE constraint failed: blog_tag.slug
Not Found: /blog/tag/delete/999/
Internal Server Error: /blog/tag/edit/1/
Traceback (most recent call last):
  File "C:\Users\admin\PycharmProjects\pythonProjectDjango\venv\Lib\site-packages\django\core\handlers\exception.py", line 55, in inner
    response = get_response(request)
               ^^^^^^^^^^^^^^^^^^^^^
  File "C:\Users\admin\PycharmProjects\pythonProjectDjango\venv\Lib\site-packages\django\core\handlers\base.py", line 197, in _get_response
    response = wrapped_callback(request, *callback_args, **callback_kwargs)
               ^^^^^^^^^^^^^^^^^^^^^^^^^^^^^^^^^^^^^^^^^^^^^^^^^^^^^^^^^^^^
  File "C:\Users\admin\PycharmProjects\pythonProjectDjango\itstep\blog\views.py", line 139, in edit_tag
    if form.is_valid():
       ^^^^^^^^^^^^^^^
  File "C:\Users\admin\PycharmProjects\pythonProjectDjango\venv\Lib\site-packages\django\forms\forms.py", line 197, in is_valid
    return self.is_bound and not self.errors
                                 ^^^^^^^^^^^
  File "C:\Users\admin\PycharmProjects\pythonProjectDjango\venv\Lib\site-packages\django\forms\forms.py", line 192, in errors
    self.full_clean()
  File "C:\Users\admin\PycharmProjects\pythonProjectDjango\venv\Lib\site-packages\django\forms\forms.py", line 328, in full_clean
    self._clean_form()
  File "C:\Users\admin\PycharmProjects\pythonProjectDjango\venv\Lib\site-packages\django\forms\forms.py", line 349, in _clean_form
    cleaned_data = self.clean()
                   ^^^^^^^^^^^^
  File "C:\Users\admin\PycharmProjects\pythonProjectDjango\itstep\blog\forms.py", line 46, in clean
    if len(cleaned_data.get("name")) < 3:
       ^^^^^^^^^^^^^^^^^^^^^^^^^^^^^
TypeError: object of type 'NoneType' has no len()
Internal Server Error: /blog/tag/create/
Traceback (most recent call last):
  File "C:\Users\admin\PycharmProjects\pythonProjectDjango\venv\Lib\site-packages\django\core\handlers\exception.py", line 55, in inner
    response = get_response(request)
               ^^^^^^^^^^^^^^^^^^^^^
  File "C:\Users\admin\PycharmProjects\pythonProjectDjango\venv\Lib\site-packages\django\core\handlers\base.py", line 197, in _get_response
    response = wrapped_callback(request, *callback_args, **callback_kwargs)
               ^^^^^^^^^^^^^^^^^^^^^^^^^^^^^^^^^^^^^^^^^^^^^^^^^^^^^^^^^^^^
  File "C:\Users\admin\PycharmProjects\pythonProjectDjango\itstep\blog\views.py", line 112, in create_tag
    if form.is_valid():
       ^^^^^^^^^^^^^^^
  File "C:\Users\admin\PycharmProjects\pythonProjectDjango\venv\Lib\site-packages\django\forms\forms.py", line 197, in is_valid
    return self.is_bound and not self.errors
                                 ^^^^^^^^^^^
  File "C:\Users\admin\PycharmProjects\pythonProjectDjango\venv\Lib\site-packages\django\forms\forms.py", line 192, in errors
    self.full_clean()
  File "C:\Users\admin\PycharmProjects\pythonProjectDjango\venv\Lib\site-packages\django\forms\forms.py", line 328, in full_clean
    self._clean_form()
  File "C:\Users\admin\PycharmProjects\pythonProjectDjango\venv\Lib\site-packages\django\forms\forms.py", line 349, in _clean_form
    cleaned_data = self.clean()
                   ^^^^^^^^^^^^
  File "C:\Users\admin\PycharmProjects\pythonProjectDjango\itstep\blog\forms.py", line 46, in clean
    if len(cleaned_data.get("name")) < 3:
       ^^^^^^^^^^^^^^^^^^^^^^^^^^^^^
TypeError: object of type 'NoneType' has no len()
Internal Server Error: /blog/tag/create/
Traceback (most recent call last):
  File "C:\Users\admin\PycharmProjects\pythonProjectDjango\venv\Lib\site-packages\django\db\backends\utils.py", line 105, in _execute
    return self.cursor.execute(sql, params)
           ^^^^^^^^^^^^^^^^^^^^^^^^^^^^^^^^
  File "C:\Users\admin\PycharmProjects\pythonProjectDjango\venv\Lib\site-packages\django\db\backends\sqlite3\base.py", line 329, in execute
    return super().execute(query, params)
           ^^^^^^^^^^^^^^^^^^^^^^^^^^^^^^
sqlite3.IntegrityError: UNIQUE constraint failed: blog_tag.slug

The above exception was the direct cause of the following exception:

Traceback (most recent call last):
  File "C:\Users\admin\PycharmProjects\pythonProjectDjango\venv\Lib\site-packages\django\core\handlers\exception.py", line 55, in inner
    response = get_response(request)
               ^^^^^^^^^^^^^^^^^^^^^
  File "C:\Users\admin\PycharmProjects\pythonProjectDjango\venv\Lib\site-packages\django\core\handlers\base.py", line 197, in _get_response
    response = wrapped_callback(request, *callback_args, **callback_kwargs)
               ^^^^^^^^^^^^^^^^^^^^^^^^^^^^^^^^^^^^^^^^^^^^^^^^^^^^^^^^^^^^
  File "C:\Users\admin\PycharmProjects\pythonProjectDjango\itstep\blog\views.py", line 116, in create_tag
    tag.save()
  File "C:\Users\admin\PycharmProjects\pythonProjectDjango\itstep\blog\models.py", line 97, in save
    super(Tag, self).save(*args, **kwargs)
  File "C:\Users\admin\PycharmProjects\pythonProjectDjango\venv\Lib\site-packages\django\db\models\base.py", line 822, in save
    self.save_base(
  File "C:\Users\admin\PycharmProjects\pythonProjectDjango\venv\Lib\site-packages\django\db\models\base.py", line 909, in save_base
    updated = self._save_table(
              ^^^^^^^^^^^^^^^^^
  File "C:\Users\admin\PycharmProjects\pythonProjectDjango\venv\Lib\site-packages\django\db\models\base.py", line 1071, in _save_table
    results = self._do_insert(
              ^^^^^^^^^^^^^^^^
  File "C:\Users\admin\PycharmProjects\pythonProjectDjango\venv\Lib\site-packages\django\db\models\base.py", line 1112, in _do_insert
    return manager._insert(
           ^^^^^^^^^^^^^^^^
  File "C:\Users\admin\PycharmProjects\pythonProjectDjango\venv\Lib\site-packages\django\db\models\manager.py", line 87, in manager_method
    return getattr(self.get_queryset(), name)(*args, **kwargs)
           ^^^^^^^^^^^^^^^^^^^^^^^^^^^^^^^^^^^^^^^^^^^^^^^^^^^
  File "C:\Users\admin\PycharmProjects\pythonProjectDjango\venv\Lib\site-packages\django\db\models\query.py", line 1847, in _insert
    return query.get_compiler(using=using).execute_sql(returning_fields)
           ^^^^^^^^^^^^^^^^^^^^^^^^^^^^^^^^^^^^^^^^^^^^^^^^^^^^^^^^^^^^^
  File "C:\Users\admin\PycharmProjects\pythonProjectDjango\venv\Lib\site-packages\django\db\models\sql\compiler.py", line 1823, in execute_sql
    cursor.execute(sql, params)
  File "C:\Users\admin\PycharmProjects\pythonProjectDjango\venv\Lib\site-packages\django\db\backends\utils.py", line 79, in execute
    return self._execute_with_wrappers(
           ^^^^^^^^^^^^^^^^^^^^^^^^^^^^
  File "C:\Users\admin\PycharmProjects\pythonProjectDjango\venv\Lib\site-packages\django\db\backends\utils.py", line 92, in _execute_with_wrappers
    return executor(sql, params, many, context)
           ^^^^^^^^^^^^^^^^^^^^^^^^^^^^^^^^^^^^
  File "C:\Users\admin\PycharmProjects\pythonProjectDjango\venv\Lib\site-packages\django\db\backends\utils.py", line 100, in _execute
    with self.db.wrap_database_errors:
  File "C:\Users\admin\PycharmProjects\pythonProjectDjango\venv\Lib\site-packages\django\db\utils.py", line 91, in __exit__
    raise dj_exc_value.with_traceback(traceback) from exc_value
  File "C:\Users\admin\PycharmProjects\pythonProjectDjango\venv\Lib\site-packages\django\db\backends\utils.py", line 105, in _execute
    return self.cursor.execute(sql, params)
           ^^^^^^^^^^^^^^^^^^^^^^^^^^^^^^^^
  File "C:\Users\admin\PycharmProjects\pythonProjectDjango\venv\Lib\site-packages\django\db\backends\sqlite3\base.py", line 329, in execute
    return super().execute(query, params)
           ^^^^^^^^^^^^^^^^^^^^^^^^^^^^^^
django.db.utils.IntegrityError: UNIQUE constraint failed: blog_tag.slug
Not Found: /blog/tag/delete/999/
Internal Server Error: /blog/tag/edit/1/
Traceback (most recent call last):
  File "C:\Users\admin\PycharmProjects\pythonProjectDjango\venv\Lib\site-packages\django\core\handlers\exception.py", line 55, in inner
    response = get_response(request)
               ^^^^^^^^^^^^^^^^^^^^^
  File "C:\Users\admin\PycharmProjects\pythonProjectDjango\venv\Lib\site-packages\django\core\handlers\base.py", line 197, in _get_response
    response = wrapped_callback(request, *callback_args, **callback_kwargs)
               ^^^^^^^^^^^^^^^^^^^^^^^^^^^^^^^^^^^^^^^^^^^^^^^^^^^^^^^^^^^^
  File "C:\Users\admin\PycharmProjects\pythonProjectDjango\itstep\blog\views.py", line 139, in edit_tag
    if form.is_valid():
       ^^^^^^^^^^^^^^^
  File "C:\Users\admin\PycharmProjects\pythonProjectDjango\venv\Lib\site-packages\django\forms\forms.py", line 197, in is_valid
    return self.is_bound and not self.errors
                                 ^^^^^^^^^^^
  File "C:\Users\admin\PycharmProjects\pythonProjectDjango\venv\Lib\site-packages\django\forms\forms.py", line 192, in errors
    self.full_clean()
  File "C:\Users\admin\PycharmProjects\pythonProjectDjango\venv\Lib\site-packages\django\forms\forms.py", line 328, in full_clean
    self._clean_form()
  File "C:\Users\admin\PycharmProjects\pythonProjectDjango\venv\Lib\site-packages\django\forms\forms.py", line 349, in _clean_form
    cleaned_data = self.clean()
                   ^^^^^^^^^^^^
  File "C:\Users\admin\PycharmProjects\pythonProjectDjango\itstep\blog\forms.py", line 46, in clean
    if len(cleaned_data.get("name")) < 3:
       ^^^^^^^^^^^^^^^^^^^^^^^^^^^^^
TypeError: object of type 'NoneType' has no len()
Internal Server Error: /blog/tag/create/
Traceback (most recent call last):
  File "C:\Users\admin\PycharmProjects\pythonProjectDjango\venv\Lib\site-packages\django\db\backends\utils.py", line 105, in _execute
    return self.cursor.execute(sql, params)
           ^^^^^^^^^^^^^^^^^^^^^^^^^^^^^^^^
  File "C:\Users\admin\PycharmProjects\pythonProjectDjango\venv\Lib\site-packages\django\db\backends\sqlite3\base.py", line 329, in execute
    return super().execute(query, params)
           ^^^^^^^^^^^^^^^^^^^^^^^^^^^^^^
sqlite3.IntegrityError: UNIQUE constraint failed: blog_tag.slug

The above exception was the direct cause of the following exception:

Traceback (most recent call last):
  File "C:\Users\admin\PycharmProjects\pythonProjectDjango\venv\Lib\site-packages\django\core\handlers\exception.py", line 55, in inner
    response = get_response(request)
               ^^^^^^^^^^^^^^^^^^^^^
  File "C:\Users\admin\PycharmProjects\pythonProjectDjango\venv\Lib\site-packages\django\core\handlers\base.py", line 197, in _get_response
    response = wrapped_callback(request, *callback_args, **callback_kwargs)
               ^^^^^^^^^^^^^^^^^^^^^^^^^^^^^^^^^^^^^^^^^^^^^^^^^^^^^^^^^^^^
  File "C:\Users\admin\PycharmProjects\pythonProjectDjango\itstep\blog\views.py", line 116, in create_tag
    tag.save()
  File "C:\Users\admin\PycharmProjects\pythonProjectDjango\itstep\blog\models.py", line 97, in save
    super(Tag, self).save(*args, **kwargs)
  File "C:\Users\admin\PycharmProjects\pythonProjectDjango\venv\Lib\site-packages\django\db\models\base.py", line 822, in save
    self.save_base(
  File "C:\Users\admin\PycharmProjects\pythonProjectDjango\venv\Lib\site-packages\django\db\models\base.py", line 909, in save_base
    updated = self._save_table(
              ^^^^^^^^^^^^^^^^^
  File "C:\Users\admin\PycharmProjects\pythonProjectDjango\venv\Lib\site-packages\django\db\models\base.py", line 1071, in _save_table
    results = self._do_insert(
              ^^^^^^^^^^^^^^^^
  File "C:\Users\admin\PycharmProjects\pythonProjectDjango\venv\Lib\site-packages\django\db\models\base.py", line 1112, in _do_insert
    return manager._insert(
           ^^^^^^^^^^^^^^^^
  File "C:\Users\admin\PycharmProjects\pythonProjectDjango\venv\Lib\site-packages\django\db\models\manager.py", line 87, in manager_method
    return getattr(self.get_queryset(), name)(*args, **kwargs)
           ^^^^^^^^^^^^^^^^^^^^^^^^^^^^^^^^^^^^^^^^^^^^^^^^^^^
  File "C:\Users\admin\PycharmProjects\pythonProjectDjango\venv\Lib\site-packages\django\db\models\query.py", line 1847, in _insert
    return query.get_compiler(using=using).execute_sql(returning_fields)
           ^^^^^^^^^^^^^^^^^^^^^^^^^^^^^^^^^^^^^^^^^^^^^^^^^^^^^^^^^^^^^
  File "C:\Users\admin\PycharmProjects\pythonProjectDjango\venv\Lib\site-packages\django\db\models\sql\compiler.py", line 1823, in execute_sql
    cursor.execute(sql, params)
  File "C:\Users\admin\PycharmProjects\pythonProjectDjango\venv\Lib\site-packages\django\db\backends\utils.py", line 79, in execute
    return self._execute_with_wrappers(
           ^^^^^^^^^^^^^^^^^^^^^^^^^^^^
  File "C:\Users\admin\PycharmProjects\pythonProjectDjango\venv\Lib\site-packages\django\db\backends\utils.py", line 92, in _execute_with_wrappers
    return executor(sql, params, many, context)
           ^^^^^^^^^^^^^^^^^^^^^^^^^^^^^^^^^^^^
  File "C:\Users\admin\PycharmProjects\pythonProjectDjango\venv\Lib\site-packages\django\db\backends\utils.py", line 100, in _execute
    with self.db.wrap_database_errors:
  File "C:\Users\admin\PycharmProjects\pythonProjectDjango\venv\Lib\site-packages\django\db\utils.py", line 91, in __exit__
    raise dj_exc_value.with_traceback(traceback) from exc_value
  File "C:\Users\admin\PycharmProjects\pythonProjectDjango\venv\Lib\site-packages\django\db\backends\utils.py", line 105, in _execute
    return self.cursor.execute(sql, params)
           ^^^^^^^^^^^^^^^^^^^^^^^^^^^^^^^^
  File "C:\Users\admin\PycharmProjects\pythonProjectDjango\venv\Lib\site-packages\django\db\backends\sqlite3\base.py", line 329, in execute
    return super().execute(query, params)
           ^^^^^^^^^^^^^^^^^^^^^^^^^^^^^^
django.db.utils.IntegrityError: UNIQUE constraint failed: blog_tag.slug
Not Found: /blog/tag/delete/999/
Internal Server Error: /blog/tag/create/
Traceback (most recent call last):
  File "C:\Users\admin\PycharmProjects\pythonProjectDjango\venv\Lib\site-packages\django\db\backends\utils.py", line 105, in _execute
    return self.cursor.execute(sql, params)
           ^^^^^^^^^^^^^^^^^^^^^^^^^^^^^^^^
  File "C:\Users\admin\PycharmProjects\pythonProjectDjango\venv\Lib\site-packages\django\db\backends\sqlite3\base.py", line 329, in execute
    return super().execute(query, params)
           ^^^^^^^^^^^^^^^^^^^^^^^^^^^^^^
sqlite3.IntegrityError: UNIQUE constraint failed: blog_tag.slug

The above exception was the direct cause of the following exception:

Traceback (most recent call last):
  File "C:\Users\admin\PycharmProjects\pythonProjectDjango\venv\Lib\site-packages\django\core\handlers\exception.py", line 55, in inner
    response = get_response(request)
               ^^^^^^^^^^^^^^^^^^^^^
  File "C:\Users\admin\PycharmProjects\pythonProjectDjango\venv\Lib\site-packages\django\core\handlers\base.py", line 197, in _get_response
    response = wrapped_callback(request, *callback_args, **callback_kwargs)
               ^^^^^^^^^^^^^^^^^^^^^^^^^^^^^^^^^^^^^^^^^^^^^^^^^^^^^^^^^^^^
  File "C:\Users\admin\PycharmProjects\pythonProjectDjango\itstep\blog\views.py", line 116, in create_tag
    tag.save()
  File "C:\Users\admin\PycharmProjects\pythonProjectDjango\itstep\blog\models.py", line 97, in save
    super(Tag, self).save(*args, **kwargs)
  File "C:\Users\admin\PycharmProjects\pythonProjectDjango\venv\Lib\site-packages\django\db\models\base.py", line 822, in save
    self.save_base(
  File "C:\Users\admin\PycharmProjects\pythonProjectDjango\venv\Lib\site-packages\django\db\models\base.py", line 909, in save_base
    updated = self._save_table(
              ^^^^^^^^^^^^^^^^^
  File "C:\Users\admin\PycharmProjects\pythonProjectDjango\venv\Lib\site-packages\django\db\models\base.py", line 1071, in _save_table
    results = self._do_insert(
              ^^^^^^^^^^^^^^^^
  File "C:\Users\admin\PycharmProjects\pythonProjectDjango\venv\Lib\site-packages\django\db\models\base.py", line 1112, in _do_insert
    return manager._insert(
           ^^^^^^^^^^^^^^^^
  File "C:\Users\admin\PycharmProjects\pythonProjectDjango\venv\Lib\site-packages\django\db\models\manager.py", line 87, in manager_method
    return getattr(self.get_queryset(), name)(*args, **kwargs)
           ^^^^^^^^^^^^^^^^^^^^^^^^^^^^^^^^^^^^^^^^^^^^^^^^^^^
  File "C:\Users\admin\PycharmProjects\pythonProjectDjango\venv\Lib\site-packages\django\db\models\query.py", line 1847, in _insert
    return query.get_compiler(using=using).execute_sql(returning_fields)
           ^^^^^^^^^^^^^^^^^^^^^^^^^^^^^^^^^^^^^^^^^^^^^^^^^^^^^^^^^^^^^
  File "C:\Users\admin\PycharmProjects\pythonProjectDjango\venv\Lib\site-packages\django\db\models\sql\compiler.py", line 1823, in execute_sql
    cursor.execute(sql, params)
  File "C:\Users\admin\PycharmProjects\pythonProjectDjango\venv\Lib\site-packages\django\db\backends\utils.py", line 79, in execute
    return self._execute_with_wrappers(
           ^^^^^^^^^^^^^^^^^^^^^^^^^^^^
  File "C:\Users\admin\PycharmProjects\pythonProjectDjango\venv\Lib\site-packages\django\db\backends\utils.py", line 92, in _execute_with_wrappers
    return executor(sql, params, many, context)
           ^^^^^^^^^^^^^^^^^^^^^^^^^^^^^^^^^^^^
  File "C:\Users\admin\PycharmProjects\pythonProjectDjango\venv\Lib\site-packages\django\db\backends\utils.py", line 100, in _execute
    with self.db.wrap_database_errors:
  File "C:\Users\admin\PycharmProjects\pythonProjectDjango\venv\Lib\site-packages\django\db\utils.py", line 91, in __exit__
    raise dj_exc_value.with_traceback(traceback) from exc_value
  File "C:\Users\admin\PycharmProjects\pythonProjectDjango\venv\Lib\site-packages\django\db\backends\utils.py", line 105, in _execute
    return self.cursor.execute(sql, params)
           ^^^^^^^^^^^^^^^^^^^^^^^^^^^^^^^^
  File "C:\Users\admin\PycharmProjects\pythonProjectDjango\venv\Lib\site-packages\django\db\backends\sqlite3\base.py", line 329, in execute
    return super().execute(query, params)
           ^^^^^^^^^^^^^^^^^^^^^^^^^^^^^^
django.db.utils.IntegrityError: UNIQUE constraint failed: blog_tag.slug
Not Found: /blog/tag/delete/999/
Internal Server Error: /blog/tag/create/
Traceback (most recent call last):
  File "C:\Users\admin\PycharmProjects\pythonProjectDjango\venv\Lib\site-packages\django\db\backends\utils.py", line 105, in _execute
    return self.cursor.execute(sql, params)
           ^^^^^^^^^^^^^^^^^^^^^^^^^^^^^^^^
  File "C:\Users\admin\PycharmProjects\pythonProjectDjango\venv\Lib\site-packages\django\db\backends\sqlite3\base.py", line 329, in execute
    return super().execute(query, params)
           ^^^^^^^^^^^^^^^^^^^^^^^^^^^^^^
sqlite3.IntegrityError: UNIQUE constraint failed: blog_tag.slug

The above exception was the direct cause of the following exception:

Traceback (most recent call last):
  File "C:\Users\admin\PycharmProjects\pythonProjectDjango\venv\Lib\site-packages\django\core\handlers\exception.py", line 55, in inner
    response = get_response(request)
               ^^^^^^^^^^^^^^^^^^^^^
  File "C:\Users\admin\PycharmProjects\pythonProjectDjango\venv\Lib\site-packages\django\core\handlers\base.py", line 197, in _get_response
    response = wrapped_callback(request, *callback_args, **callback_kwargs)
               ^^^^^^^^^^^^^^^^^^^^^^^^^^^^^^^^^^^^^^^^^^^^^^^^^^^^^^^^^^^^
  File "C:\Users\admin\PycharmProjects\pythonProjectDjango\itstep\blog\views.py", line 116, in create_tag
    tag.save()
  File "C:\Users\admin\PycharmProjects\pythonProjectDjango\itstep\blog\models.py", line 97, in save
    super(Tag, self).save(*args, **kwargs)
  File "C:\Users\admin\PycharmProjects\pythonProjectDjango\venv\Lib\site-packages\django\db\models\base.py", line 822, in save
    self.save_base(
  File "C:\Users\admin\PycharmProjects\pythonProjectDjango\venv\Lib\site-packages\django\db\models\base.py", line 909, in save_base
    updated = self._save_table(
              ^^^^^^^^^^^^^^^^^
  File "C:\Users\admin\PycharmProjects\pythonProjectDjango\venv\Lib\site-packages\django\db\models\base.py", line 1071, in _save_table
    results = self._do_insert(
              ^^^^^^^^^^^^^^^^
  File "C:\Users\admin\PycharmProjects\pythonProjectDjango\venv\Lib\site-packages\django\db\models\base.py", line 1112, in _do_insert
    return manager._insert(
           ^^^^^^^^^^^^^^^^
  File "C:\Users\admin\PycharmProjects\pythonProjectDjango\venv\Lib\site-packages\django\db\models\manager.py", line 87, in manager_method
    return getattr(self.get_queryset(), name)(*args, **kwargs)
           ^^^^^^^^^^^^^^^^^^^^^^^^^^^^^^^^^^^^^^^^^^^^^^^^^^^
  File "C:\Users\admin\PycharmProjects\pythonProjectDjango\venv\Lib\site-packages\django\db\models\query.py", line 1847, in _insert
    return query.get_compiler(using=using).execute_sql(returning_fields)
           ^^^^^^^^^^^^^^^^^^^^^^^^^^^^^^^^^^^^^^^^^^^^^^^^^^^^^^^^^^^^^
  File "C:\Users\admin\PycharmProjects\pythonProjectDjango\venv\Lib\site-packages\django\db\models\sql\compiler.py", line 1823, in execute_sql
    cursor.execute(sql, params)
  File "C:\Users\admin\PycharmProjects\pythonProjectDjango\venv\Lib\site-packages\django\db\backends\utils.py", line 79, in execute
    return self._execute_with_wrappers(
           ^^^^^^^^^^^^^^^^^^^^^^^^^^^^
  File "C:\Users\admin\PycharmProjects\pythonProjectDjango\venv\Lib\site-packages\django\db\backends\utils.py", line 92, in _execute_with_wrappers
    return executor(sql, params, many, context)
           ^^^^^^^^^^^^^^^^^^^^^^^^^^^^^^^^^^^^
  File "C:\Users\admin\PycharmProjects\pythonProjectDjango\venv\Lib\site-packages\django\db\backends\utils.py", line 100, in _execute
    with self.db.wrap_database_errors:
  File "C:\Users\admin\PycharmProjects\pythonProjectDjango\venv\Lib\site-packages\django\db\utils.py", line 91, in __exit__
    raise dj_exc_value.with_traceback(traceback) from exc_value
  File "C:\Users\admin\PycharmProjects\pythonProjectDjango\venv\Lib\site-packages\django\db\backends\utils.py", line 105, in _execute
    return self.cursor.execute(sql, params)
           ^^^^^^^^^^^^^^^^^^^^^^^^^^^^^^^^
  File "C:\Users\admin\PycharmProjects\pythonProjectDjango\venv\Lib\site-packages\django\db\backends\sqlite3\base.py", line 329, in execute
    return super().execute(query, params)
           ^^^^^^^^^^^^^^^^^^^^^^^^^^^^^^
django.db.utils.IntegrityError: UNIQUE constraint failed: blog_tag.slug
Not Found: /blog/tag/delete/999/
Internal Server Error: /blog/tag/create/
Traceback (most recent call last):
  File "C:\Users\admin\PycharmProjects\pythonProjectDjango\venv\Lib\site-packages\django\db\backends\utils.py", line 105, in _execute
    return self.cursor.execute(sql, params)
           ^^^^^^^^^^^^^^^^^^^^^^^^^^^^^^^^
  File "C:\Users\admin\PycharmProjects\pythonProjectDjango\venv\Lib\site-packages\django\db\backends\sqlite3\base.py", line 329, in execute
    return super().execute(query, params)
           ^^^^^^^^^^^^^^^^^^^^^^^^^^^^^^
sqlite3.IntegrityError: UNIQUE constraint failed: blog_tag.slug

The above exception was the direct cause of the following exception:

Traceback (most recent call last):
  File "C:\Users\admin\PycharmProjects\pythonProjectDjango\venv\Lib\site-packages\django\core\handlers\exception.py", line 55, in inner
    response = get_response(request)
               ^^^^^^^^^^^^^^^^^^^^^
  File "C:\Users\admin\PycharmProjects\pythonProjectDjango\venv\Lib\site-packages\django\core\handlers\base.py", line 197, in _get_response
    response = wrapped_callback(request, *callback_args, **callback_kwargs)
               ^^^^^^^^^^^^^^^^^^^^^^^^^^^^^^^^^^^^^^^^^^^^^^^^^^^^^^^^^^^^
  File "C:\Users\admin\PycharmProjects\pythonProjectDjango\itstep\blog\views.py", line 116, in create_tag
    tag.save()
  File "C:\Users\admin\PycharmProjects\pythonProjectDjango\itstep\blog\models.py", line 97, in save
    super(Tag, self).save(*args, **kwargs)
  File "C:\Users\admin\PycharmProjects\pythonProjectDjango\venv\Lib\site-packages\django\db\models\base.py", line 822, in save
    self.save_base(
  File "C:\Users\admin\PycharmProjects\pythonProjectDjango\venv\Lib\site-packages\django\db\models\base.py", line 909, in save_base
    updated = self._save_table(
              ^^^^^^^^^^^^^^^^^
  File "C:\Users\admin\PycharmProjects\pythonProjectDjango\venv\Lib\site-packages\django\db\models\base.py", line 1071, in _save_table
    results = self._do_insert(
              ^^^^^^^^^^^^^^^^
  File "C:\Users\admin\PycharmProjects\pythonProjectDjango\venv\Lib\site-packages\django\db\models\base.py", line 1112, in _do_insert
    return manager._insert(
           ^^^^^^^^^^^^^^^^
  File "C:\Users\admin\PycharmProjects\pythonProjectDjango\venv\Lib\site-packages\django\db\models\manager.py", line 87, in manager_method
    return getattr(self.get_queryset(), name)(*args, **kwargs)
           ^^^^^^^^^^^^^^^^^^^^^^^^^^^^^^^^^^^^^^^^^^^^^^^^^^^
  File "C:\Users\admin\PycharmProjects\pythonProjectDjango\venv\Lib\site-packages\django\db\models\query.py", line 1847, in _insert
    return query.get_compiler(using=using).execute_sql(returning_fields)
           ^^^^^^^^^^^^^^^^^^^^^^^^^^^^^^^^^^^^^^^^^^^^^^^^^^^^^^^^^^^^^
  File "C:\Users\admin\PycharmProjects\pythonProjectDjango\venv\Lib\site-packages\django\db\models\sql\compiler.py", line 1823, in execute_sql
    cursor.execute(sql, params)
  File "C:\Users\admin\PycharmProjects\pythonProjectDjango\venv\Lib\site-packages\django\db\backends\utils.py", line 79, in execute
    return self._execute_with_wrappers(
           ^^^^^^^^^^^^^^^^^^^^^^^^^^^^
  File "C:\Users\admin\PycharmProjects\pythonProjectDjango\venv\Lib\site-packages\django\db\backends\utils.py", line 92, in _execute_with_wrappers
    return executor(sql, params, many, context)
           ^^^^^^^^^^^^^^^^^^^^^^^^^^^^^^^^^^^^
  File "C:\Users\admin\PycharmProjects\pythonProjectDjango\venv\Lib\site-packages\django\db\backends\utils.py", line 100, in _execute
    with self.db.wrap_database_errors:
  File "C:\Users\admin\PycharmProjects\pythonProjectDjango\venv\Lib\site-packages\django\db\utils.py", line 91, in __exit__
    raise dj_exc_value.with_traceback(traceback) from exc_value
  File "C:\Users\admin\PycharmProjects\pythonProjectDjango\venv\Lib\site-packages\django\db\backends\utils.py", line 105, in _execute
    return self.cursor.execute(sql, params)
           ^^^^^^^^^^^^^^^^^^^^^^^^^^^^^^^^
  File "C:\Users\admin\PycharmProjects\pythonProjectDjango\venv\Lib\site-packages\django\db\backends\sqlite3\base.py", line 329, in execute
    return super().execute(query, params)
           ^^^^^^^^^^^^^^^^^^^^^^^^^^^^^^
django.db.utils.IntegrityError: UNIQUE constraint failed: blog_tag.slug
Not Found: /blog/tag/delete/999/
Internal Server Error: /blog/tag/create/
Traceback (most recent call last):
  File "C:\Users\admin\PycharmProjects\pythonProjectDjango\venv\Lib\site-packages\django\db\backends\utils.py", line 105, in _execute
    return self.cursor.execute(sql, params)
           ^^^^^^^^^^^^^^^^^^^^^^^^^^^^^^^^
  File "C:\Users\admin\PycharmProjects\pythonProjectDjango\venv\Lib\site-packages\django\db\backends\sqlite3\base.py", line 329, in execute
    return super().execute(query, params)
           ^^^^^^^^^^^^^^^^^^^^^^^^^^^^^^
sqlite3.IntegrityError: UNIQUE constraint failed: blog_tag.slug

The above exception was the direct cause of the following exception:

Traceback (most recent call last):
  File "C:\Users\admin\PycharmProjects\pythonProjectDjango\venv\Lib\site-packages\django\core\handlers\exception.py", line 55, in inner
    response = get_response(request)
               ^^^^^^^^^^^^^^^^^^^^^
  File "C:\Users\admin\PycharmProjects\pythonProjectDjango\venv\Lib\site-packages\django\core\handlers\base.py", line 197, in _get_response
    response = wrapped_callback(request, *callback_args, **callback_kwargs)
               ^^^^^^^^^^^^^^^^^^^^^^^^^^^^^^^^^^^^^^^^^^^^^^^^^^^^^^^^^^^^
  File "C:\Users\admin\PycharmProjects\pythonProjectDjango\itstep\blog\views.py", line 116, in create_tag
    tag.save()
  File "C:\Users\admin\PycharmProjects\pythonProjectDjango\itstep\blog\models.py", line 97, in save
    super(Tag, self).save(*args, **kwargs)
  File "C:\Users\admin\PycharmProjects\pythonProjectDjango\venv\Lib\site-packages\django\db\models\base.py", line 822, in save
    self.save_base(
  File "C:\Users\admin\PycharmProjects\pythonProjectDjango\venv\Lib\site-packages\django\db\models\base.py", line 909, in save_base
    updated = self._save_table(
              ^^^^^^^^^^^^^^^^^
  File "C:\Users\admin\PycharmProjects\pythonProjectDjango\venv\Lib\site-packages\django\db\models\base.py", line 1071, in _save_table
    results = self._do_insert(
              ^^^^^^^^^^^^^^^^
  File "C:\Users\admin\PycharmProjects\pythonProjectDjango\venv\Lib\site-packages\django\db\models\base.py", line 1112, in _do_insert
    return manager._insert(
           ^^^^^^^^^^^^^^^^
  File "C:\Users\admin\PycharmProjects\pythonProjectDjango\venv\Lib\site-packages\django\db\models\manager.py", line 87, in manager_method
    return getattr(self.get_queryset(), name)(*args, **kwargs)
           ^^^^^^^^^^^^^^^^^^^^^^^^^^^^^^^^^^^^^^^^^^^^^^^^^^^
  File "C:\Users\admin\PycharmProjects\pythonProjectDjango\venv\Lib\site-packages\django\db\models\query.py", line 1847, in _insert
    return query.get_compiler(using=using).execute_sql(returning_fields)
           ^^^^^^^^^^^^^^^^^^^^^^^^^^^^^^^^^^^^^^^^^^^^^^^^^^^^^^^^^^^^^
  File "C:\Users\admin\PycharmProjects\pythonProjectDjango\venv\Lib\site-packages\django\db\models\sql\compiler.py", line 1823, in execute_sql
    cursor.execute(sql, params)
  File "C:\Users\admin\PycharmProjects\pythonProjectDjango\venv\Lib\site-packages\django\db\backends\utils.py", line 79, in execute
    return self._execute_with_wrappers(
           ^^^^^^^^^^^^^^^^^^^^^^^^^^^^
  File "C:\Users\admin\PycharmProjects\pythonProjectDjango\venv\Lib\site-packages\django\db\backends\utils.py", line 92, in _execute_with_wrappers
    return executor(sql, params, many, context)
           ^^^^^^^^^^^^^^^^^^^^^^^^^^^^^^^^^^^^
  File "C:\Users\admin\PycharmProjects\pythonProjectDjango\venv\Lib\site-packages\django\db\backends\utils.py", line 100, in _execute
    with self.db.wrap_database_errors:
  File "C:\Users\admin\PycharmProjects\pythonProjectDjango\venv\Lib\site-packages\django\db\utils.py", line 91, in __exit__
    raise dj_exc_value.with_traceback(traceback) from exc_value
  File "C:\Users\admin\PycharmProjects\pythonProjectDjango\venv\Lib\site-packages\django\db\backends\utils.py", line 105, in _execute
    return self.cursor.execute(sql, params)
           ^^^^^^^^^^^^^^^^^^^^^^^^^^^^^^^^
  File "C:\Users\admin\PycharmProjects\pythonProjectDjango\venv\Lib\site-packages\django\db\backends\sqlite3\base.py", line 329, in execute
    return super().execute(query, params)
           ^^^^^^^^^^^^^^^^^^^^^^^^^^^^^^
django.db.utils.IntegrityError: UNIQUE constraint failed: blog_tag.slug
Not Found: /blog/tag/delete/999/
Watching for file changes with StatReloader
"GET / HTTP/1.1" 200 23097
"GET /static/css/styles.css HTTP/1.1" 304 0
"GET /static/images/logo.png HTTP/1.1" 304 0
"GET /static/debug_toolbar/css/toolbar.css HTTP/1.1" 304 0
"GET /static/images/sky.jpg HTTP/1.1" 304 0
"GET /static/debug_toolbar/js/toolbar.js HTTP/1.1" 304 0
"GET /static/debug_toolbar/css/print.css HTTP/1.1" 304 0
"GET /static/debug_toolbar/js/utils.js HTTP/1.1" 304 0
Not Found: /favicon.ico
"GET /favicon.ico HTTP/1.1" 404 16532
"GET /blog/cards/ HTTP/1.1" 200 36824
"GET /media/post/images/4.jpg HTTP/1.1" 200 5320
"GET /media/default.png HTTP/1.1" 200 1724
"GET /media/post/images/sqlA.JPG HTTP/1.1" 200 6502
"GET /media/post/images/28.JPG HTTP/1.1" 200 24780
"GET /media/post/images/5.JPG HTTP/1.1" 200 36745
"GET /media/post/images/%D0%9E%D0%B1%D0%BA%D0%BB%D0%B0%D0%B4%D0%B8%D0%BD%D0%BA%D0%B0.JPG HTTP/1.1" 200 323216
"GET /blog/2/ HTTP/1.1" 200 20108
"GET /blog/edit/2/ HTTP/1.1" 200 21891
"POST /blog/edit/2/ HTTP/1.1" 302 0
"GET /blog/2/ HTTP/1.1" 200 20222
"GET /account/ HTTP/1.1" 200 18681
"GET /media/users/2024/09/02/photo-1549692520-acc6669e2f0c_FM85C9b.jpg HTTP/1.1" 200 13473
"GET /account/edit/ HTTP/1.1" 200 19995
"POST /account/logout/ HTTP/1.1" 200 18162
"GET /account/register/ HTTP/1.1" 200 20028
"GET /account/login/ HTTP/1.1" 200 19385
"GET /static/images/login.png HTTP/1.1" 304 0
"POST /account/login/ HTTP/1.1" 302 0
"GET /account/ HTTP/1.1" 200 18681
"GET /account/ HTTP/1.1" 200 18682
"GET /blog/cards/ HTTP/1.1" 200 36827
"GET /blog/3/ HTTP/1.1" 200 19878
"GET /blog/edit/3/ HTTP/1.1" 200 21667
Internal Server Error: /blog/tag/create/
Traceback (most recent call last):
  File "C:\Users\admin\PycharmProjects\pythonProjectDjango\venv\Lib\site-packages\django\db\backends\utils.py", line 105, in _execute
    return self.cursor.execute(sql, params)
           ^^^^^^^^^^^^^^^^^^^^^^^^^^^^^^^^
  File "C:\Users\admin\PycharmProjects\pythonProjectDjango\venv\Lib\site-packages\django\db\backends\sqlite3\base.py", line 329, in execute
    return super().execute(query, params)
           ^^^^^^^^^^^^^^^^^^^^^^^^^^^^^^
sqlite3.IntegrityError: UNIQUE constraint failed: blog_tag.slug

The above exception was the direct cause of the following exception:

Traceback (most recent call last):
  File "C:\Users\admin\PycharmProjects\pythonProjectDjango\venv\Lib\site-packages\django\core\handlers\exception.py", line 55, in inner
    response = get_response(request)
               ^^^^^^^^^^^^^^^^^^^^^
  File "C:\Users\admin\PycharmProjects\pythonProjectDjango\venv\Lib\site-packages\django\core\handlers\base.py", line 197, in _get_response
    response = wrapped_callback(request, *callback_args, **callback_kwargs)
               ^^^^^^^^^^^^^^^^^^^^^^^^^^^^^^^^^^^^^^^^^^^^^^^^^^^^^^^^^^^^
  File "C:\Users\admin\PycharmProjects\pythonProjectDjango\itstep\blog\views.py", line 116, in create_tag
    tag.save()
  File "C:\Users\admin\PycharmProjects\pythonProjectDjango\itstep\blog\models.py", line 97, in save
    super(Tag, self).save(*args, **kwargs)
  File "C:\Users\admin\PycharmProjects\pythonProjectDjango\venv\Lib\site-packages\django\db\models\base.py", line 822, in save
    self.save_base(
  File "C:\Users\admin\PycharmProjects\pythonProjectDjango\venv\Lib\site-packages\django\db\models\base.py", line 909, in save_base
    updated = self._save_table(
              ^^^^^^^^^^^^^^^^^
  File "C:\Users\admin\PycharmProjects\pythonProjectDjango\venv\Lib\site-packages\django\db\models\base.py", line 1071, in _save_table
    results = self._do_insert(
              ^^^^^^^^^^^^^^^^
  File "C:\Users\admin\PycharmProjects\pythonProjectDjango\venv\Lib\site-packages\django\db\models\base.py", line 1112, in _do_insert
    return manager._insert(
           ^^^^^^^^^^^^^^^^
  File "C:\Users\admin\PycharmProjects\pythonProjectDjango\venv\Lib\site-packages\django\db\models\manager.py", line 87, in manager_method
    return getattr(self.get_queryset(), name)(*args, **kwargs)
           ^^^^^^^^^^^^^^^^^^^^^^^^^^^^^^^^^^^^^^^^^^^^^^^^^^^
  File "C:\Users\admin\PycharmProjects\pythonProjectDjango\venv\Lib\site-packages\django\db\models\query.py", line 1847, in _insert
    return query.get_compiler(using=using).execute_sql(returning_fields)
           ^^^^^^^^^^^^^^^^^^^^^^^^^^^^^^^^^^^^^^^^^^^^^^^^^^^^^^^^^^^^^
  File "C:\Users\admin\PycharmProjects\pythonProjectDjango\venv\Lib\site-packages\django\db\models\sql\compiler.py", line 1823, in execute_sql
    cursor.execute(sql, params)
  File "C:\Users\admin\PycharmProjects\pythonProjectDjango\venv\Lib\site-packages\django\db\backends\utils.py", line 79, in execute
    return self._execute_with_wrappers(
           ^^^^^^^^^^^^^^^^^^^^^^^^^^^^
  File "C:\Users\admin\PycharmProjects\pythonProjectDjango\venv\Lib\site-packages\django\db\backends\utils.py", line 92, in _execute_with_wrappers
    return executor(sql, params, many, context)
           ^^^^^^^^^^^^^^^^^^^^^^^^^^^^^^^^^^^^
  File "C:\Users\admin\PycharmProjects\pythonProjectDjango\venv\Lib\site-packages\django\db\backends\utils.py", line 100, in _execute
    with self.db.wrap_database_errors:
  File "C:\Users\admin\PycharmProjects\pythonProjectDjango\venv\Lib\site-packages\django\db\utils.py", line 91, in __exit__
    raise dj_exc_value.with_traceback(traceback) from exc_value
  File "C:\Users\admin\PycharmProjects\pythonProjectDjango\venv\Lib\site-packages\django\db\backends\utils.py", line 105, in _execute
    return self.cursor.execute(sql, params)
           ^^^^^^^^^^^^^^^^^^^^^^^^^^^^^^^^
  File "C:\Users\admin\PycharmProjects\pythonProjectDjango\venv\Lib\site-packages\django\db\backends\sqlite3\base.py", line 329, in execute
    return super().execute(query, params)
           ^^^^^^^^^^^^^^^^^^^^^^^^^^^^^^
django.db.utils.IntegrityError: UNIQUE constraint failed: blog_tag.slug
Not Found: /blog/tag/delete/999/
Internal Server Error: /blog/tag/create/
Traceback (most recent call last):
  File "C:\Users\admin\PycharmProjects\pythonProjectDjango\venv\Lib\site-packages\django\db\backends\utils.py", line 105, in _execute
    return self.cursor.execute(sql, params)
           ^^^^^^^^^^^^^^^^^^^^^^^^^^^^^^^^
  File "C:\Users\admin\PycharmProjects\pythonProjectDjango\venv\Lib\site-packages\django\db\backends\sqlite3\base.py", line 329, in execute
    return super().execute(query, params)
           ^^^^^^^^^^^^^^^^^^^^^^^^^^^^^^
sqlite3.IntegrityError: UNIQUE constraint failed: blog_tag.slug

The above exception was the direct cause of the following exception:

Traceback (most recent call last):
  File "C:\Users\admin\PycharmProjects\pythonProjectDjango\venv\Lib\site-packages\django\core\handlers\exception.py", line 55, in inner
    response = get_response(request)
               ^^^^^^^^^^^^^^^^^^^^^
  File "C:\Users\admin\PycharmProjects\pythonProjectDjango\venv\Lib\site-packages\django\core\handlers\base.py", line 197, in _get_response
    response = wrapped_callback(request, *callback_args, **callback_kwargs)
               ^^^^^^^^^^^^^^^^^^^^^^^^^^^^^^^^^^^^^^^^^^^^^^^^^^^^^^^^^^^^
  File "C:\Users\admin\PycharmProjects\pythonProjectDjango\itstep\blog\views.py", line 116, in create_tag
    tag.save()
  File "C:\Users\admin\PycharmProjects\pythonProjectDjango\itstep\blog\models.py", line 97, in save
    super(Tag, self).save(*args, **kwargs)
  File "C:\Users\admin\PycharmProjects\pythonProjectDjango\venv\Lib\site-packages\django\db\models\base.py", line 822, in save
    self.save_base(
  File "C:\Users\admin\PycharmProjects\pythonProjectDjango\venv\Lib\site-packages\django\db\models\base.py", line 909, in save_base
    updated = self._save_table(
              ^^^^^^^^^^^^^^^^^
  File "C:\Users\admin\PycharmProjects\pythonProjectDjango\venv\Lib\site-packages\django\db\models\base.py", line 1071, in _save_table
    results = self._do_insert(
              ^^^^^^^^^^^^^^^^
  File "C:\Users\admin\PycharmProjects\pythonProjectDjango\venv\Lib\site-packages\django\db\models\base.py", line 1112, in _do_insert
    return manager._insert(
           ^^^^^^^^^^^^^^^^
  File "C:\Users\admin\PycharmProjects\pythonProjectDjango\venv\Lib\site-packages\django\db\models\manager.py", line 87, in manager_method
    return getattr(self.get_queryset(), name)(*args, **kwargs)
           ^^^^^^^^^^^^^^^^^^^^^^^^^^^^^^^^^^^^^^^^^^^^^^^^^^^
  File "C:\Users\admin\PycharmProjects\pythonProjectDjango\venv\Lib\site-packages\django\db\models\query.py", line 1847, in _insert
    return query.get_compiler(using=using).execute_sql(returning_fields)
           ^^^^^^^^^^^^^^^^^^^^^^^^^^^^^^^^^^^^^^^^^^^^^^^^^^^^^^^^^^^^^
  File "C:\Users\admin\PycharmProjects\pythonProjectDjango\venv\Lib\site-packages\django\db\models\sql\compiler.py", line 1823, in execute_sql
    cursor.execute(sql, params)
  File "C:\Users\admin\PycharmProjects\pythonProjectDjango\venv\Lib\site-packages\django\db\backends\utils.py", line 79, in execute
    return self._execute_with_wrappers(
           ^^^^^^^^^^^^^^^^^^^^^^^^^^^^
  File "C:\Users\admin\PycharmProjects\pythonProjectDjango\venv\Lib\site-packages\django\db\backends\utils.py", line 92, in _execute_with_wrappers
    return executor(sql, params, many, context)
           ^^^^^^^^^^^^^^^^^^^^^^^^^^^^^^^^^^^^
  File "C:\Users\admin\PycharmProjects\pythonProjectDjango\venv\Lib\site-packages\django\db\backends\utils.py", line 100, in _execute
    with self.db.wrap_database_errors:
  File "C:\Users\admin\PycharmProjects\pythonProjectDjango\venv\Lib\site-packages\django\db\utils.py", line 91, in __exit__
    raise dj_exc_value.with_traceback(traceback) from exc_value
  File "C:\Users\admin\PycharmProjects\pythonProjectDjango\venv\Lib\site-packages\django\db\backends\utils.py", line 105, in _execute
    return self.cursor.execute(sql, params)
           ^^^^^^^^^^^^^^^^^^^^^^^^^^^^^^^^
  File "C:\Users\admin\PycharmProjects\pythonProjectDjango\venv\Lib\site-packages\django\db\backends\sqlite3\base.py", line 329, in execute
    return super().execute(query, params)
           ^^^^^^^^^^^^^^^^^^^^^^^^^^^^^^
django.db.utils.IntegrityError: UNIQUE constraint failed: blog_tag.slug
Not Found: /blog/tag/delete/999/
Internal Server Error: /blog/tag/create/
Traceback (most recent call last):
  File "C:\Users\admin\PycharmProjects\pythonProjectDjango\venv\Lib\site-packages\django\db\backends\utils.py", line 105, in _execute
    return self.cursor.execute(sql, params)
           ^^^^^^^^^^^^^^^^^^^^^^^^^^^^^^^^
  File "C:\Users\admin\PycharmProjects\pythonProjectDjango\venv\Lib\site-packages\django\db\backends\sqlite3\base.py", line 329, in execute
    return super().execute(query, params)
           ^^^^^^^^^^^^^^^^^^^^^^^^^^^^^^
sqlite3.IntegrityError: UNIQUE constraint failed: blog_tag.slug

The above exception was the direct cause of the following exception:

Traceback (most recent call last):
  File "C:\Users\admin\PycharmProjects\pythonProjectDjango\venv\Lib\site-packages\django\core\handlers\exception.py", line 55, in inner
    response = get_response(request)
               ^^^^^^^^^^^^^^^^^^^^^
  File "C:\Users\admin\PycharmProjects\pythonProjectDjango\venv\Lib\site-packages\django\core\handlers\base.py", line 197, in _get_response
    response = wrapped_callback(request, *callback_args, **callback_kwargs)
               ^^^^^^^^^^^^^^^^^^^^^^^^^^^^^^^^^^^^^^^^^^^^^^^^^^^^^^^^^^^^
  File "C:\Users\admin\PycharmProjects\pythonProjectDjango\itstep\blog\views.py", line 116, in create_tag
    tag.save()
  File "C:\Users\admin\PycharmProjects\pythonProjectDjango\itstep\blog\models.py", line 97, in save
    super(Tag, self).save(*args, **kwargs)
  File "C:\Users\admin\PycharmProjects\pythonProjectDjango\venv\Lib\site-packages\django\db\models\base.py", line 822, in save
    self.save_base(
  File "C:\Users\admin\PycharmProjects\pythonProjectDjango\venv\Lib\site-packages\django\db\models\base.py", line 909, in save_base
    updated = self._save_table(
              ^^^^^^^^^^^^^^^^^
  File "C:\Users\admin\PycharmProjects\pythonProjectDjango\venv\Lib\site-packages\django\db\models\base.py", line 1071, in _save_table
    results = self._do_insert(
              ^^^^^^^^^^^^^^^^
  File "C:\Users\admin\PycharmProjects\pythonProjectDjango\venv\Lib\site-packages\django\db\models\base.py", line 1112, in _do_insert
    return manager._insert(
           ^^^^^^^^^^^^^^^^
  File "C:\Users\admin\PycharmProjects\pythonProjectDjango\venv\Lib\site-packages\django\db\models\manager.py", line 87, in manager_method
    return getattr(self.get_queryset(), name)(*args, **kwargs)
           ^^^^^^^^^^^^^^^^^^^^^^^^^^^^^^^^^^^^^^^^^^^^^^^^^^^
  File "C:\Users\admin\PycharmProjects\pythonProjectDjango\venv\Lib\site-packages\django\db\models\query.py", line 1847, in _insert
    return query.get_compiler(using=using).execute_sql(returning_fields)
           ^^^^^^^^^^^^^^^^^^^^^^^^^^^^^^^^^^^^^^^^^^^^^^^^^^^^^^^^^^^^^
  File "C:\Users\admin\PycharmProjects\pythonProjectDjango\venv\Lib\site-packages\django\db\models\sql\compiler.py", line 1823, in execute_sql
    cursor.execute(sql, params)
  File "C:\Users\admin\PycharmProjects\pythonProjectDjango\venv\Lib\site-packages\django\db\backends\utils.py", line 79, in execute
    return self._execute_with_wrappers(
           ^^^^^^^^^^^^^^^^^^^^^^^^^^^^
  File "C:\Users\admin\PycharmProjects\pythonProjectDjango\venv\Lib\site-packages\django\db\backends\utils.py", line 92, in _execute_with_wrappers
    return executor(sql, params, many, context)
           ^^^^^^^^^^^^^^^^^^^^^^^^^^^^^^^^^^^^
  File "C:\Users\admin\PycharmProjects\pythonProjectDjango\venv\Lib\site-packages\django\db\backends\utils.py", line 100, in _execute
    with self.db.wrap_database_errors:
  File "C:\Users\admin\PycharmProjects\pythonProjectDjango\venv\Lib\site-packages\django\db\utils.py", line 91, in __exit__
    raise dj_exc_value.with_traceback(traceback) from exc_value
  File "C:\Users\admin\PycharmProjects\pythonProjectDjango\venv\Lib\site-packages\django\db\backends\utils.py", line 105, in _execute
    return self.cursor.execute(sql, params)
           ^^^^^^^^^^^^^^^^^^^^^^^^^^^^^^^^
  File "C:\Users\admin\PycharmProjects\pythonProjectDjango\venv\Lib\site-packages\django\db\backends\sqlite3\base.py", line 329, in execute
    return super().execute(query, params)
           ^^^^^^^^^^^^^^^^^^^^^^^^^^^^^^
django.db.utils.IntegrityError: UNIQUE constraint failed: blog_tag.slug
Internal Server Error: /blog/tag/create/
Traceback (most recent call last):
  File "C:\Users\admin\PycharmProjects\pythonProjectDjango\venv\Lib\site-packages\django\db\backends\utils.py", line 105, in _execute
    return self.cursor.execute(sql, params)
           ^^^^^^^^^^^^^^^^^^^^^^^^^^^^^^^^
  File "C:\Users\admin\PycharmProjects\pythonProjectDjango\venv\Lib\site-packages\django\db\backends\sqlite3\base.py", line 329, in execute
    return super().execute(query, params)
           ^^^^^^^^^^^^^^^^^^^^^^^^^^^^^^
sqlite3.IntegrityError: UNIQUE constraint failed: blog_tag.slug

The above exception was the direct cause of the following exception:

Traceback (most recent call last):
  File "C:\Users\admin\PycharmProjects\pythonProjectDjango\venv\Lib\site-packages\django\core\handlers\exception.py", line 55, in inner
    response = get_response(request)
               ^^^^^^^^^^^^^^^^^^^^^
  File "C:\Users\admin\PycharmProjects\pythonProjectDjango\venv\Lib\site-packages\django\core\handlers\base.py", line 197, in _get_response
    response = wrapped_callback(request, *callback_args, **callback_kwargs)
               ^^^^^^^^^^^^^^^^^^^^^^^^^^^^^^^^^^^^^^^^^^^^^^^^^^^^^^^^^^^^
  File "C:\Users\admin\PycharmProjects\pythonProjectDjango\itstep\blog\views.py", line 116, in create_tag
    tag.save()
  File "C:\Users\admin\PycharmProjects\pythonProjectDjango\itstep\blog\models.py", line 97, in save
    super(Tag, self).save(*args, **kwargs)
  File "C:\Users\admin\PycharmProjects\pythonProjectDjango\venv\Lib\site-packages\django\db\models\base.py", line 822, in save
    self.save_base(
  File "C:\Users\admin\PycharmProjects\pythonProjectDjango\venv\Lib\site-packages\django\db\models\base.py", line 909, in save_base
    updated = self._save_table(
              ^^^^^^^^^^^^^^^^^
  File "C:\Users\admin\PycharmProjects\pythonProjectDjango\venv\Lib\site-packages\django\db\models\base.py", line 1071, in _save_table
    results = self._do_insert(
              ^^^^^^^^^^^^^^^^
  File "C:\Users\admin\PycharmProjects\pythonProjectDjango\venv\Lib\site-packages\django\db\models\base.py", line 1112, in _do_insert
    return manager._insert(
           ^^^^^^^^^^^^^^^^
  File "C:\Users\admin\PycharmProjects\pythonProjectDjango\venv\Lib\site-packages\django\db\models\manager.py", line 87, in manager_method
    return getattr(self.get_queryset(), name)(*args, **kwargs)
           ^^^^^^^^^^^^^^^^^^^^^^^^^^^^^^^^^^^^^^^^^^^^^^^^^^^
  File "C:\Users\admin\PycharmProjects\pythonProjectDjango\venv\Lib\site-packages\django\db\models\query.py", line 1847, in _insert
    return query.get_compiler(using=using).execute_sql(returning_fields)
           ^^^^^^^^^^^^^^^^^^^^^^^^^^^^^^^^^^^^^^^^^^^^^^^^^^^^^^^^^^^^^
  File "C:\Users\admin\PycharmProjects\pythonProjectDjango\venv\Lib\site-packages\django\db\models\sql\compiler.py", line 1823, in execute_sql
    cursor.execute(sql, params)
  File "C:\Users\admin\PycharmProjects\pythonProjectDjango\venv\Lib\site-packages\django\db\backends\utils.py", line 79, in execute
    return self._execute_with_wrappers(
           ^^^^^^^^^^^^^^^^^^^^^^^^^^^^
  File "C:\Users\admin\PycharmProjects\pythonProjectDjango\venv\Lib\site-packages\django\db\backends\utils.py", line 92, in _execute_with_wrappers
    return executor(sql, params, many, context)
           ^^^^^^^^^^^^^^^^^^^^^^^^^^^^^^^^^^^^
  File "C:\Users\admin\PycharmProjects\pythonProjectDjango\venv\Lib\site-packages\django\db\backends\utils.py", line 100, in _execute
    with self.db.wrap_database_errors:
  File "C:\Users\admin\PycharmProjects\pythonProjectDjango\venv\Lib\site-packages\django\db\utils.py", line 91, in __exit__
    raise dj_exc_value.with_traceback(traceback) from exc_value
  File "C:\Users\admin\PycharmProjects\pythonProjectDjango\venv\Lib\site-packages\django\db\backends\utils.py", line 105, in _execute
    return self.cursor.execute(sql, params)
           ^^^^^^^^^^^^^^^^^^^^^^^^^^^^^^^^
  File "C:\Users\admin\PycharmProjects\pythonProjectDjango\venv\Lib\site-packages\django\db\backends\sqlite3\base.py", line 329, in execute
    return super().execute(query, params)
           ^^^^^^^^^^^^^^^^^^^^^^^^^^^^^^
django.db.utils.IntegrityError: UNIQUE constraint failed: blog_tag.slug
Watching for file changes with StatReloader
"GET / HTTP/1.1" 200 22826
"GET /static/debug_toolbar/css/toolbar.css HTTP/1.1" 304 0
"GET /static/debug_toolbar/js/toolbar.js HTTP/1.1" 304 0
"GET /static/debug_toolbar/css/print.css HTTP/1.1" 304 0
"GET /static/debug_toolbar/js/utils.js HTTP/1.1" 304 0
"GET /account/login/ HTTP/1.1" 200 19385
"GET /static/images/login.png HTTP/1.1" 304 0
Not Found: /blog/tag/delete/999/
Not Found: /blog/tag/delete/999/
Not Found: /blog/tag/delete/999/
Not Found: /blog/tag/delete/999/
Not Found: /blog/tag/delete/999/
Not Found: /blog/tag/delete/999/
Not Found: /blog/tag/delete/999/
Not Found: /blog/tag/delete/999/
Not Found: /blog/tag/delete/999/
Not Found: /blog/tag/delete/999/
Not Found: /blog/tag/delete/999/
Not Found: /blog/tag/delete/999/
Not Found: /blog/tag/delete/999/
Not Found: /blog/tag/delete/999/
Not Found: /blog/tag/delete/999/
Not Found: /blog/tag/delete/999/
Not Found: /blog/tag/delete/999/
Not Found: /blog/tag/delete/999/
Not Found: /blog/tag/delete/999/
Not Found: /blog/tag/delete/999/
Not Found: /blog/tag/delete/999/
Not Found: /blog/tag/delete/999/
Not Found: /blog/tag/delete/999/
Not Found: /blog/tag/delete/999/
Not Found: /blog/tag/delete/999/
Not Found: /blog/tag/delete/999/
Not Found: /blog/tag/delete/999/
Not Found: /blog/tag/delete/999/
Not Found: /blog/tag/delete/999/
Not Found: /blog/tag/delete/999/
Not Found: /blog/tag/delete/999/
Not Found: /blog/tag/delete/999/
Not Found: /blog/tag/delete/999/
Not Found: /blog/tag/delete/999/
Not Found: /blog/tag/delete/999/
Not Found: /blog/tag/delete/999/
Not Found: /blog/tag/delete/999/
Not Found: /blog/tag/delete/999/
Not Found: /blog/tag/delete/999/
Not Found: /blog/tag/delete/999/
Not Found: /blog/tag/delete/999/
Not Found: /blog/tag/delete/999/
Not Found: /blog/tag/delete/999/
Not Found: /blog/tag/delete/999/
Not Found: /blog/tag/delete/999/
Not Found: /blog/tag/delete/999/
Not Found: /blog/tag/delete/999/
Not Found: /blog/tag/delete/999/
Not Found: /blog/tag/delete/999/
Not Found: /blog/tag/delete/999/
Not Found: /blog/tag/delete/999/
Not Found: /blog/tag/delete/999/
Not Found: /blog/tag/delete/999/
Not Found: /blog/tag/delete/999/
Not Found: /blog/tag/delete/999/
Not Found: /blog/tag/delete/999/
Not Found: /blog/tag/delete/999/
Not Found: /blog/tag/delete/999/
Not Found: /blog/tag/delete/999/
Not Found: /blog/tag/delete/999/
Not Found: /blog/tag/delete/999/
Not Found: /blog/tag/delete/999/
Not Found: /blog/tag/delete/999/
